Workbook
Name Slicer_Diabetes_Status: #N/A
Name Slicer_Weight_Status: #N/A

Sheet Customer Names
A1: Customer ID | B1: name | C1: First Name | D1: title | E1: Lat Name
A2: Id1 | B2: Hawks, Ms. Kelly | C2: =_xlfn.TEXTBEFORE(B2," ") -> Hawks, | D2: =_xlfn.TEXTBEFORE(_xlfn.TEXTAFTER(B2," ")," ") -> Ms. | E2: =_xlfn.TEXTAFTER(B2," ",-1) -> Kelly
A3: Id2 | B3: Lehner, Mr. Matthew D | C3: =_xlfn.TEXTBEFORE(B3," ") -> Lehner, | D3: =_xlfn.TEXTBEFORE(_xlfn.TEXTAFTER(B3," ")," ") -> Mr. | E3: =_xlfn.TEXTAFTER(B3," ",-1) -> D
A4: Id3 | B4: Lu, Mr. Phil | C4: =_xlfn.TEXTBEFORE(B4," ") -> Lu, | D4: =_xlfn.TEXTBEFORE(_xlfn.TEXTAFTER(B4," ")," ") -> Mr. | E4: =_xlfn.TEXTAFTER(B4," ",-1) -> Phil
A5: Id4 | B5: Osborne, Ms. Kelsey | C5: =_xlfn.TEXTBEFORE(B5," ") -> Osborne, | D5: =_xlfn.TEXTBEFORE(_xlfn.TEXTAFTER(B5," ")," ") -> Ms. | E5: =_xlfn.TEXTAFTER(B5," ",-1) -> Kelsey
A6: Id5 | B6: Kadala, Ms. Kristyn | C6: =_xlfn.TEXTBEFORE(B6," ") -> Kadala, | D6: =_xlfn.TEXTBEFORE(_xlfn.TEXTAFTER(B6," ")," ") -> Ms. | E6: =_xlfn.TEXTAFTER(B6," ",-1) -> Kristyn
A7: Id6 | B7: Baker, Mr. Russell B. | C7: =_xlfn.TEXTBEFORE(B7," ") -> Baker, | D7: =_xlfn.TEXTBEFORE(_xlfn.TEXTAFTER(B7," ")," ") -> Mr. | E7: =_xlfn.TEXTAFTER(B7," ",-1) -> B.
A8: Id7 | B8: Macpherson, Mr. Scott | C8: =_xlfn.TEXTBEFORE(B8," ") -> Macpherson, | D8: =_xlfn.TEXTBEFORE(_xlfn.TEXTAFTER(B8," ")," ") -> Mr. | E8: =_xlfn.TEXTAFTER(B8," ",-1) -> Scott
A9: Id8 | B9: Hallman, Mr. Stephen | C9: =_xlfn.TEXTBEFORE(B9," ") -> Hallman, | D9: =_xlfn.TEXTBEFORE(_xlfn.TEXTAFTER(B9," ")," ") -> Mr. | E9: =_xlfn.TEXTAFTER(B9," ",-1) -> Stephen
A10: Id9 | B10: Moran, Mr. Patrick R. | C10: =_xlfn.TEXTBEFORE(B10," ") -> Moran, | D10: =_xlfn.TEXTBEFORE(_xlfn.TEXTAFTER(B10," ")," ") -> Mr. | E10: =_xlfn.TEXTAFTER(B10," ",-1) -> R.
A11: Id10 | B11: Benner, Ms. Brooke N. | C11: =_xlfn.TEXTBEFORE(B11," ") -> Benner, | D11: =_xlfn.TEXTBEFORE(_xlfn.TEXTAFTER(B11," ")," ") -> Ms. | E11: =_xlfn.TEXTAFTER(B11," ",-1) -> N.
A12: Id11 | B12: Fierro Vargas, Ms. Paola Andrea | C12: =_xlfn.TEXTBEFORE(B12," ") -> Fierro | D12: =_xlfn.TEXTBEFORE(_xlfn.TEXTAFTER(B12," ")," ") -> Vargas, | E12: =_xlfn.TEXTAFTER(B12," ",-1) -> Andrea
A13: Id12 | B13: Franz, Mr. David | C13: =_xlfn.TEXTBEFORE(B13," ") -> Franz, | D13: =_xlfn.TEXTBEFORE(_xlfn.TEXTAFTER(B13," ")," ") -> Mr. | E13: =_xlfn.TEXTAFTER(B13," ",-1) -> David
... A587: Id586 | B587: Rotich, Ms. Caroline | C587: =_xlfn.TEXTBEFORE(B587," ") -> Rotich, | D587: =_xlfn.TEXTBEFORE(_xlfn.TEXTAFTER(B587," ")," ") -> Ms. | E587: =_xlfn.TEXTAFTER(B587," ",-1) -> Caroline
A588: Id587 | B588: Fetzer, Ms. Alexis N | D588: =_xlfn.TEXTBEFORE(_xlfn.TEXTAFTER(B588," ")," ") -> Ms. | E588: =_xlfn.TEXTAFTER(B588," ",-1) -> N
A589: Id588 | B589: Mattis, Ms. Shanda L | D589: =_xlfn.TEXTBEFORE(_xlfn.TEXTAFTER(B589," ")," ") -> Ms. | E589: =_xlfn.TEXTAFTER(B589," ",-1) -> L
A590: Id589 | B590: Cochran, Mrs. Lacey | D590: =_xlfn.TEXTBEFORE(_xlfn.TEXTAFTER(B590," ")," ") -> Mrs. | E590: =_xlfn.TEXTAFTER(B590," ",-1) -> Lacey
A591: Id590 | B591: Balinsky, Ms. Laurette | D591: =_xlfn.TEXTBEFORE(_xlfn.TEXTAFTER(B591," ")," ") -> Ms. | E591: =_xlfn.TEXTAFTER(B591," ",-1) -> Laurette
A592: Id591 | B592: Reilly, Mr. Jason | D592: =_xlfn.TEXTBEFORE(_xlfn.TEXTAFTER(B592," ")," ") -> Mr. | E592: =_xlfn.TEXTAFTER(B592," ",-1) -> Jason
A593: Id592 | B593: Johnson, Ms. Mary | D593: =_xlfn.TEXTBEFORE(_xlfn.TEXTAFTER(B593," ")," ") -> Ms. | E593: =_xlfn.TEXTAFTER(B593," ",-1) -> Mary
A594: Id593 | B594: Petry, Ms. Kati A | D594: =_xlfn.TEXTBEFORE(_xlfn.TEXTAFTER(B594," ")," ") -> Ms. | E594: =_xlfn.TEXTAFTER(B594," ",-1) -> A
A595: Id594 | B595: Laleman, Mrs. Kelly J | D595: =_xlfn.TEXTBEFORE(_xlfn.TEXTAFTER(B595," ")," ") -> Mrs. | E595: =_xlfn.TEXTAFTER(B595," ",-1) -> J
A596: Id595 | B596: Colby, Ms. Greer D | D596: =_xlfn.TEXTBEFORE(_xlfn.TEXTAFTER(B596," ")," ") -> Ms. | E596: =_xlfn.TEXTAFTER(B596," ",-1) -> D
A597: Id596 | B597: Wathke, Mr. Brent | D597: =_xlfn.TEXTBEFORE(_xlfn.TEXTAFTER(B597," ")," ") -> Mr. | E597: =_xlfn.TEXTAFTER(B597," ",-1) -> Brent
A598: Id597 | B598: Daly, Mr. Eugene M | D598: =_xlfn.TEXTBEFORE(_xlfn.TEXTAFTER(B598," ")," ") -> Mr. | E598: =_xlfn.TEXTAFTER(B598," ",-1) -> M
A599: Id598 | B599: Dillon, Ms. Erin D | D599: =_xlfn.TEXTBEFORE(_xlfn.TEXTAFTER(B599," ")," ") -> Ms. | E599: =_xlfn.TEXTAFTER(B599," ",-1) -> D
... A612: Id611 | B612: Neems, Mr. Justin | D612: =_xlfn.TEXTBEFORE(_xlfn.TEXTAFTER(B612," ")," ") -> Mr. | E612: =_xlfn.TEXTAFTER(B612," ",-1) -> Justin
A613: Id612 | B613: Pesyna, Ms. Megan A. | E613: =_xlfn.TEXTAFTER(B613," ",-1) -> A.
A614: Id613 | B614: Meling, Ms. Erika M. | E614: =_xlfn.TEXTAFTER(B614," ",-1) -> M.
A615: Id614 | B615: Widlowski, Mr. Daniel G. | E615: =_xlfn.TEXTAFTER(B615," ",-1) -> G.
A616: Id615 | B616: Nadar, Ms. Devin C. | E616: =_xlfn.TEXTAFTER(B616," ",-1) -> C.
A617: Id616 | B617: Turner, Ms. Louise A | E617: =_xlfn.TEXTAFTER(B617," ",-1) -> A
A618: Id617 | B618: Walker, Mrs. Sarah | E618: =_xlfn.TEXTAFTER(B618," ",-1) -> Sarah
A619: Id618 | B619: Leedham, Ms. Amy | E619: =_xlfn.TEXTAFTER(B619," ",-1) -> Amy
A620: Id619 | B620: Haglund, Ms. Brittany L. | E620: =_xlfn.TEXTAFTER(B620," ",-1) -> L.
A621: Id620 | B621: Mills, Ms. Jessica L | E621: =_xlfn.TEXTAFTER(B621," ",-1) -> L
A622: Id621 | B622: Drnjevich, Mrs. Kristina K | E622: =_xlfn.TEXTAFTER(B622," ",-1) -> K
A623: Id622 | B623: Clay, Mr. Brad | E623: =_xlfn.TEXTAFTER(B623," ",-1) -> Brad
A624: Id623 | B624: Marbury, Ms. Margaret O | E624: =_xlfn.TEXTAFTER(B624," ",-1) -> O
... A637: Id636 | B637: Stoney, Mrs. Hilda | E637: =_xlfn.TEXTAFTER(B637," ",-1) -> Hilda
...

Sheet Medical Examinations
A1: Customer ID | B1: BMI | C1: Weight Status | D1: HBA1C | E1: Diabetes Status | F1: Heart Issues | G1: Column1 | H1: Any Transplants | I1: Cancer history | J1: NumberOfMajorSurgeries | K1: Smoker | L1: Column2 | N1: Missing values = 2
A2: Id1 | B2: 47.41 | C2: =IF(Table1[[#This Row],[BMI]]="","",IF(Table1[[#This Row],[BMI]]<18.5,"Underweight",IF(Table1[[#This Row],[BMI]]<25,"Normal Weight",IF(Table1[[#This Row],[BMI]]<30,"Overweight","Obesity")))) -> Obesity | D2: 7.47 | E2: =IF(OR(Table1[[#This Row],[HBA1C]]="",Table1[[#This Row],[HBA1C]]="?"),"",IF(Table1[[#This Row],[HBA1C]]<5.7,"Normal",IF(Table1[[#This Row],[HBA1C]]<6.5,"Prediabetes","Diabetes"))) -> Diabetes | F2: No | G2: =IF(OR(Table1[[#This Row],[Heart Issues]]="Yes",Table1[[#This Row],[Heart Issues]]="No"),"OK","Check") -> OK | H2: No | I2: No | J2: 0 | K2: yes | L2: =IF(OR(Table1[[#This Row],[Smoker]]="Yes",Table1[[#This Row],[Smoker]]="No"),"OK","Check") -> OK | N2: Replacing missing values with no
A3: Id2 | B3: 30.36 | C3: =IF(Table1[[#This Row],[BMI]]="","",IF(Table1[[#This Row],[BMI]]<18.5,"Underweight",IF(Table1[[#This Row],[BMI]]<25,"Normal Weight",IF(Table1[[#This Row],[BMI]]<30,"Overweight","Obesity")))) -> Obesity | D3: 5.77 | E3: =IF(OR(Table1[[#This Row],[HBA1C]]="",Table1[[#This Row],[HBA1C]]="?"),"",IF(Table1[[#This Row],[HBA1C]]<5.7,"Normal",IF(Table1[[#This Row],[HBA1C]]<6.5,"Prediabetes","Diabetes"))) -> Prediabetes | F3: No | G3: =IF(OR(Table1[[#This Row],[Heart Issues]]="Yes",Table1[[#This Row],[Heart Issues]]="No"),"OK","Check") -> OK | H3: No | I3: No | J3: 0 | K3: yes | L3: =IF(OR(Table1[[#This Row],[Smoker]]="Yes",Table1[[#This Row],[Smoker]]="No"),"OK","Check") -> OK | M3: yes | N3: =COUNTIF(K:K,"Yes") -> 488
A4: Id3 | B4: 34.485 | C4: =IF(Table1[[#This Row],[BMI]]="","",IF(Table1[[#This Row],[BMI]]<18.5,"Underweight",IF(Table1[[#This Row],[BMI]]<25,"Normal Weight",IF(Table1[[#This Row],[BMI]]<30,"Overweight","Obesity")))) -> Obesity | D4: 11.87 | E4: =IF(OR(Table1[[#This Row],[HBA1C]]="",Table1[[#This Row],[HBA1C]]="?"),"",IF(Table1[[#This Row],[HBA1C]]<5.7,"Normal",IF(Table1[[#This Row],[HBA1C]]<6.5,"Prediabetes","Diabetes"))) -> Diabetes | F4: yes | G4: =IF(OR(Table1[[#This Row],[Heart Issues]]="Yes",Table1[[#This Row],[Heart Issues]]="No"),"OK","Check") -> OK | H4: No | I4: No | J4: 2 | K4: yes | L4: =IF(OR(Table1[[#This Row],[Smoker]]="Yes",Table1[[#This Row],[Smoker]]="No"),"OK","Check") -> OK | M4: No | N4: =COUNTIF(K:K,"No") -> 1845
A5: Id4 | B5: 38.095 | C5: =IF(Table1[[#This Row],[BMI]]="","",IF(Table1[[#This Row],[BMI]]<18.5,"Underweight",IF(Table1[[#This Row],[BMI]]<25,"Normal Weight",IF(Table1[[#This Row],[BMI]]<30,"Overweight","Obesity")))) -> Obesity | D5: 6.05 | E5: =IF(OR(Table1[[#This Row],[HBA1C]]="",Table1[[#This Row],[HBA1C]]="?"),"",IF(Table1[[#This Row],[HBA1C]]<5.7,"Normal",IF(Table1[[#This Row],[HBA1C]]<6.5,"Prediabetes","Diabetes"))) -> Prediabetes | F5: No | G5: =IF(OR(Table1[[#This Row],[Heart Issues]]="Yes",Table1[[#This Row],[Heart Issues]]="No"),"OK","Check") -> OK | H5: No | I5: No | J5: 0 | K5: yes | L5: =IF(OR(Table1[[#This Row],[Smoker]]="Yes",Table1[[#This Row],[Smoker]]="No"),"OK","Check") -> OK
A6: Id5 | B6: 35.53 | C6: =IF(Table1[[#This Row],[BMI]]="","",IF(Table1[[#This Row],[BMI]]<18.5,"Underweight",IF(Table1[[#This Row],[BMI]]<25,"Normal Weight",IF(Table1[[#This Row],[BMI]]<30,"Overweight","Obesity")))) -> Obesity | D6: 5.45 | E6: =IF(OR(Table1[[#This Row],[HBA1C]]="",Table1[[#This Row],[HBA1C]]="?"),"",IF(Table1[[#This Row],[HBA1C]]<5.7,"Normal",IF(Table1[[#This Row],[HBA1C]]<6.5,"Prediabetes","Diabetes"))) -> Normal | F6: No | G6: =IF(OR(Table1[[#This Row],[Heart Issues]]="Yes",Table1[[#This Row],[Heart Issues]]="No"),"OK","Check") -> OK | H6: No | I6: No | J6: 0 | K6: yes | L6: =IF(OR(Table1[[#This Row],[Smoker]]="Yes",Table1[[#This Row],[Smoker]]="No"),"OK","Check") -> OK
A7: Id6 | B7: 32.8 | C7: =IF(Table1[[#This Row],[BMI]]="","",IF(Table1[[#This Row],[BMI]]<18.5,"Underweight",IF(Table1[[#This Row],[BMI]]<25,"Normal Weight",IF(Table1[[#This Row],[BMI]]<30,"Overweight","Obesity")))) -> Obesity | D7: 6.59 | E7: =IF(OR(Table1[[#This Row],[HBA1C]]="",Table1[[#This Row],[HBA1C]]="?"),"",IF(Table1[[#This Row],[HBA1C]]<5.7,"Normal",IF(Table1[[#This Row],[HBA1C]]<6.5,"Prediabetes","Diabetes"))) -> Diabetes | F7: No | G7: =IF(OR(Table1[[#This Row],[Heart Issues]]="Yes",Table1[[#This Row],[Heart Issues]]="No"),"OK","Check") -> OK | H7: No | I7: No | J7: 0 | K7: yes | L7: =IF(OR(Table1[[#This Row],[Smoker]]="Yes",Table1[[#This Row],[Smoker]]="No"),"OK","Check") -> OK
A8: Id7 | B8: 36.4 | C8: =IF(Table1[[#This Row],[BMI]]="","",IF(Table1[[#This Row],[BMI]]<18.5,"Underweight",IF(Table1[[#This Row],[BMI]]<25,"Normal Weight",IF(Table1[[#This Row],[BMI]]<30,"Overweight","Obesity")))) -> Obesity | D8: 6.07 | E8: =IF(OR(Table1[[#This Row],[HBA1C]]="",Table1[[#This Row],[HBA1C]]="?"),"",IF(Table1[[#This Row],[HBA1C]]<5.7,"Normal",IF(Table1[[#This Row],[HBA1C]]<6.5,"Prediabetes","Diabetes"))) -> Prediabetes | F8: No | G8: =IF(OR(Table1[[#This Row],[Heart Issues]]="Yes",Table1[[#This Row],[Heart Issues]]="No"),"OK","Check") -> OK | H8: No | I8: No | J8: 0 | K8: yes | L8: =IF(OR(Table1[[#This Row],[Smoker]]="Yes",Table1[[#This Row],[Smoker]]="No"),"OK","Check") -> OK
A9: Id8 | B9: 36.96 | C9: =IF(Table1[[#This Row],[BMI]]="","",IF(Table1[[#This Row],[BMI]]<18.5,"Underweight",IF(Table1[[#This Row],[BMI]]<25,"Normal Weight",IF(Table1[[#This Row],[BMI]]<30,"Overweight","Obesity")))) -> Obesity | D9: 7.93 | E9: =IF(OR(Table1[[#This Row],[HBA1C]]="",Table1[[#This Row],[HBA1C]]="?"),"",IF(Table1[[#This Row],[HBA1C]]<5.7,"Normal",IF(Table1[[#This Row],[HBA1C]]<6.5,"Prediabetes","Diabetes"))) -> Diabetes | F9: No | G9: =IF(OR(Table1[[#This Row],[Heart Issues]]="Yes",Table1[[#This Row],[Heart Issues]]="No"),"OK","Check") -> OK | H9: No | I9: No | J9: 3 | K9: yes | L9: =IF(OR(Table1[[#This Row],[Smoker]]="Yes",Table1[[#This Row],[Smoker]]="No"),"OK","Check") -> OK
A10: Id9 | B10: 41.14 | C10: =IF(Table1[[#This Row],[BMI]]="","",IF(Table1[[#This Row],[BMI]]<18.5,"Underweight",IF(Table1[[#This Row],[BMI]]<25,"Normal Weight",IF(Table1[[#This Row],[BMI]]<30,"Overweight","Obesity")))) -> Obesity | D10: 9.58 | E10: =IF(OR(Table1[[#This Row],[HBA1C]]="",Table1[[#This Row],[HBA1C]]="?"),"",IF(Table1[[#This Row],[HBA1C]]<5.7,"Normal",IF(Table1[[#This Row],[HBA1C]]<6.5,"Prediabetes","Diabetes"))) -> Diabetes | F10: yes | G10: =IF(OR(Table1[[#This Row],[Heart Issues]]="Yes",Table1[[#This Row],[Heart Issues]]="No"),"OK","Check") -> OK | H10: No | I10: Yes | J10: 1 | K10: yes | L10: =IF(OR(Table1[[#This Row],[Smoker]]="Yes",Table1[[#This Row],[Smoker]]="No"),"OK","Check") -> OK
A11: Id10 | B11: 38.06 | C11: =IF(Table1[[#This Row],[BMI]]="","",IF(Table1[[#This Row],[BMI]]<18.5,"Underweight",IF(Table1[[#This Row],[BMI]]<25,"Normal Weight",IF(Table1[[#This Row],[BMI]]<30,"Overweight","Obesity")))) -> Obesity | D11: 10.79 | E11: =IF(OR(Table1[[#This Row],[HBA1C]]="",Table1[[#This Row],[HBA1C]]="?"),"",IF(Table1[[#This Row],[HBA1C]]<5.7,"Normal",IF(Table1[[#This Row],[HBA1C]]<6.5,"Prediabetes","Diabetes"))) -> Diabetes | F11: No | G11: =IF(OR(Table1[[#This Row],[Heart Issues]]="Yes",Table1[[#This Row],[Heart Issues]]="No"),"OK","Check") -> OK | H11: No | I11: No | J11: 0 | K11: yes | L11: =IF(OR(Table1[[#This Row],[Smoker]]="Yes",Table1[[#This Row],[Smoker]]="No"),"OK","Check") -> OK
A12: Id11 | B12: 37.7 | C12: =IF(Table1[[#This Row],[BMI]]="","",IF(Table1[[#This Row],[BMI]]<18.5,"Underweight",IF(Table1[[#This Row],[BMI]]<25,"Normal Weight",IF(Table1[[#This Row],[BMI]]<30,"Overweight","Obesity")))) -> Obesity | D12: 5.96 | E12: =IF(OR(Table1[[#This Row],[HBA1C]]="",Table1[[#This Row],[HBA1C]]="?"),"",IF(Table1[[#This Row],[HBA1C]]<5.7,"Normal",IF(Table1[[#This Row],[HBA1C]]<6.5,"Prediabetes","Diabetes"))) -> Prediabetes | F12: yes | G12: =IF(OR(Table1[[#This Row],[Heart Issues]]="Yes",Table1[[#This Row],[Heart Issues]]="No"),"OK","Check") -> OK | H12: No | I12: No | J12: 2 | K12: yes | L12: =IF(OR(Table1[[#This Row],[Smoker]]="Yes",Table1[[#This Row],[Smoker]]="No"),"OK","Check") -> OK
A13: Id12 | B13: 42.13 | C13: =IF(Table1[[#This Row],[BMI]]="","",IF(Table1[[#This Row],[BMI]]<18.5,"Underweight",IF(Table1[[#This Row],[BMI]]<25,"Normal Weight",IF(Table1[[#This Row],[BMI]]<30,"Overweight","Obesity")))) -> Obesity | D13: 11.9 | E13: =IF(OR(Table1[[#This Row],[HBA1C]]="",Table1[[#This Row],[HBA1C]]="?"),"",IF(Table1[[#This Row],[HBA1C]]<5.7,"Normal",IF(Table1[[#This Row],[HBA1C]]<6.5,"Prediabetes","Diabetes"))) -> Diabetes | F13: No | G13: =IF(OR(Table1[[#This Row],[Heart Issues]]="Yes",Table1[[#This Row],[Heart Issues]]="No"),"OK","Check") -> OK | H13: No | I13: No | J13: 0 | K13: yes | L13: =IF(OR(Table1[[#This Row],[Smoker]]="Yes",Table1[[#This Row],[Smoker]]="No"),"OK","Check") -> OK
A14: Id13 | B14: 40.92 | C14: =IF(Table1[[#This Row],[BMI]]="","",IF(Table1[[#This Row],[BMI]]<18.5,"Underweight",IF(Table1[[#This Row],[BMI]]<25,"Normal Weight",IF(Table1[[#This Row],[BMI]]<30,"Overweight","Obesity")))) -> Obesity | D14: 8.41 | E14: =IF(OR(Table1[[#This Row],[HBA1C]]="",Table1[[#This Row],[HBA1C]]="?"),"",IF(Table1[[#This Row],[HBA1C]]<5.7,"Normal",IF(Table1[[#This Row],[HBA1C]]<6.5,"Prediabetes","Diabetes"))) -> Diabetes | F14: No | G14: =IF(OR(Table1[[#This Row],[Heart Issues]]="Yes",Table1[[#This Row],[Heart Issues]]="No"),"OK","Check") -> OK | H14: No | I14: No | J14: 0 | K14: yes | L14: =IF(OR(Table1[[#This Row],[Smoker]]="Yes",Table1[[#This Row],[Smoker]]="No"),"OK","Check") -> OK
A15: Id14 | B15: 40.565 | C15: =IF(Table1[[#This Row],[BMI]]="","",IF(Table1[[#This Row],[BMI]]<18.5,"Underweight",IF(Table1[[#This Row],[BMI]]<25,"Normal Weight",IF(Table1[[#This Row],[BMI]]<30,"Overweight","Obesity")))) -> Obesity | D15: 7.02 | E15: =IF(OR(Table1[[#This Row],[HBA1C]]="",Table1[[#This Row],[HBA1C]]="?"),"",IF(Table1[[#This Row],[HBA1C]]<5.7,"Normal",IF(Table1[[#This Row],[HBA1C]]<6.5,"Prediabetes","Diabetes"))) -> Diabetes | F15: No | G15: =IF(OR(Table1[[#This Row],[Heart Issues]]="Yes",Table1[[#This Row],[Heart Issues]]="No"),"OK","Check") -> OK | H15: No | I15: No | J15: 0 | K15: yes | L15: =IF(OR(Table1[[#This Row],[Smoker]]="Yes",Table1[[#This Row],[Smoker]]="No"),"OK","Check") -> OK
A16: Id15 | B16: 36.385 | C16: =IF(Table1[[#This Row],[BMI]]="","",IF(Table1[[#This Row],[BMI]]<18.5,"Underweight",IF(Table1[[#This Row],[BMI]]<25,"Normal Weight",IF(Table1[[#This Row],[BMI]]<30,"Overweight","Obesity")))) -> Obesity | D16: 7.59 | E16: =IF(OR(Table1[[#This Row],[HBA1C]]="",Table1[[#This Row],[HBA1C]]="?"),"",IF(Table1[[#This Row],[HBA1C]]<5.7,"Normal",IF(Table1[[#This Row],[HBA1C]]<6.5,"Prediabetes","Diabetes"))) -> Diabetes | F16: yes | G16: =IF(OR(Table1[[#This Row],[Heart Issues]]="Yes",Table1[[#This Row],[Heart Issues]]="No"),"OK","Check") -> OK | H16: No | I16: No | J16: 2 | K16: yes | L16: =IF(OR(Table1[[#This Row],[Smoker]]="Yes",Table1[[#This Row],[Smoker]]="No"),"OK","Check") -> OK
... A2336: Id2335 | B2336: 17.58 | C2336: =IF(Table1[[#This Row],[BMI]]="","",IF(Table1[[#This Row],[BMI]]<18.5,"Underweight",IF(Table1[[#This Row],[BMI]]<25,"Normal Weight",IF(Table1[[#This Row],[BMI]]<30,"Overweight","Obesity")))) -> Underweight | D2336: 4.51 | E2336: =IF(OR(Table1[[#This Row],[HBA1C]]="",Table1[[#This Row],[HBA1C]]="?"),"",IF(Table1[[#This Row],[HBA1C]]<5.7,"Normal",IF(Table1[[#This Row],[HBA1C]]<6.5,"Prediabetes","Diabetes"))) -> Normal | F2336: No | G2336: =IF(OR(Table1[[#This Row],[Heart Issues]]="Yes",Table1[[#This Row],[Heart Issues]]="No"),"OK","Check") -> OK | H2336: No | I2336: No | J2336: 1 | K2336: No | L2336: =IF(OR(Table1[[#This Row],[Smoker]]="Yes",Table1[[#This Row],[Smoker]]="No"),"OK","Check") -> OK

Sheet Hospitalisation Details
A1: Customer ID | B1: year | C1: month | D1: Month | E1: date | F1: D.O.B | G1: children | H1: Age | I1: charges | J1: Hospital tier | K1: City tier | L1: State ID | M1: State ID | P1: Rounded average | R1: State id | W1: Age | X1: HbA1c | Y1: Age | Z1: BMI
A2: Id2335 | B2: 1992 | C2: Jul | D2: =IF(C2="?","Sep",C2) -> Jul | E2: 9 | F2: =TEXT(DATE(B2,MONTH(DATEVALUE(D2&" 1")),E2),"dd-mmm-yyyy") -> 09-Jul-1992 | G2: 0 | H2: =DATEDIF(G2,TODAY(),"Y") -> 126 | I2: 563.84 | J2: tier - 2 | K2: tier - 3 | L2: R1013 | M2: =IF(L2="?","Unknown",L2) -> R1013 | P2: =ROUND(AVERAGE(B:B),0) -> 1983 | R2: =COUNTIF(L:L,"~?") -> 2 | W2: =DATEDIF(F2,TODAY(),"Y") -> 34 | X2: =VLOOKUP($A2,'Medical Examinations'!$A:$Z,MATCH(X$1,'Medical Examinations'!$A$1:$Z$1,0),FALSE) -> 4.51 | Y2: =DATEDIF(X2,TODAY(),"Y") -> 126 | Z2: =VLOOKUP($A2,'Medical Examinations'!$A:$Z,2,FALSE) -> 17.58
A3: Id2334 | B3: 1992 | C3: Nov | D3: =IF(C3="?","Sep",C3) -> Nov | E3: 30 | F3: =TEXT(DATE(B3,MONTH(DATEVALUE(D3&" 1")),E3),"dd-mmm-yyyy") -> 30-Nov-1992 | G3: 0 | H3: =DATEDIF(G3,TODAY(),"Y") -> 126 | I3: 570.62 | J3: tier - 2 | K3: tier - 1 | L3: R1013 | M3: =IF(L3="?","Unknown",L3) -> R1013 | W3: =DATEDIF(F3,TODAY(),"Y") -> 33 | X3: =VLOOKUP($A3,'Medical Examinations'!$A:$Z,MATCH(X$1,'Medical Examinations'!$A$1:$Z$1,0),FALSE) -> 4.39 | Y3: =DATEDIF(X3,TODAY(),"Y") -> 126 | Z3: =VLOOKUP($A3,'Medical Examinations'!$A:$Z,2,FALSE) -> 17.6
A4: Id2333 | B4: 1993 | C4: Jun | D4: =IF(C4="?","Sep",C4) -> Jun | E4: 30 | F4: =TEXT(DATE(B4,MONTH(DATEVALUE(D4&" 1")),E4),"dd-mmm-yyyy") -> 30-Jun-1993 | G4: 0 | H4: =DATEDIF(G4,TODAY(),"Y") -> 126 | I4: 600 | J4: tier - 2 | K4: tier - 1 | L4: R1013 | M4: =IF(L4="?","Unknown",L4) -> R1013 | W4: =DATEDIF(F4,TODAY(),"Y") -> 33 | X4: =VLOOKUP($A4,'Medical Examinations'!$A:$Z,MATCH(X$1,'Medical Examinations'!$A$1:$Z$1,0),FALSE) -> 6.35 | Y4: =DATEDIF(X4,TODAY(),"Y") -> 126 | Z4: =VLOOKUP($A4,'Medical Examinations'!$A:$Z,2,FALSE) -> 16.47
A5: Id2332 | B5: 1992 | C5: Sep | D5: =IF(C5="?","Sep",C5) -> Sep | E5: 13 | F5: =TEXT(DATE(B5,MONTH(DATEVALUE(D5&" 1")),E5),"dd-mmm-yyyy") -> 13-Sep-1992 | G5: 0 | H5: =DATEDIF(G5,TODAY(),"Y") -> 126 | I5: 604.54 | J5: tier - 3 | K5: tier - 3 | L5: R1013 | M5: =IF(L5="?","Unknown",L5) -> R1013 | W5: =DATEDIF(F5,TODAY(),"Y") -> 34 | X5: =VLOOKUP($A5,'Medical Examinations'!$A:$Z,MATCH(X$1,'Medical Examinations'!$A$1:$Z$1,0),FALSE) -> 6.28 | Y5: =DATEDIF(X5,TODAY(),"Y") -> 126 | Z5: =VLOOKUP($A5,'Medical Examinations'!$A:$Z,2,FALSE) -> 17.7
A6: Id2331 | B6: 1998 | C6: Jul | D6: =IF(C6="?","Sep",C6) -> Jul | E6: 27 | F6: =TEXT(DATE(B6,MONTH(DATEVALUE(D6&" 1")),E6),"dd-mmm-yyyy") -> 27-Jul-1998 | G6: 0 | H6: =DATEDIF(G6,TODAY(),"Y") -> 126 | I6: 637.26 | J6: tier - 3 | K6: tier - 3 | L6: R1013 | M6: =IF(L6="?","Unknown",L6) -> R1013 | W6: =DATEDIF(F6,TODAY(),"Y") -> 28 | X6: =VLOOKUP($A6,'Medical Examinations'!$A:$Z,MATCH(X$1,'Medical Examinations'!$A$1:$Z$1,0),FALSE) -> 5.57 | Y6: =DATEDIF(X6,TODAY(),"Y") -> 126 | Z6: =VLOOKUP($A6,'Medical Examinations'!$A:$Z,2,FALSE) -> 22.34
A7: Id2330 | B7: 2001 | C7: Nov | D7: =IF(C7="?","Sep",C7) -> Nov | E7: 20 | F7: =TEXT(DATE(B7,MONTH(DATEVALUE(D7&" 1")),E7),"dd-mmm-yyyy") -> 20-Nov-2001 | G7: 0 | H7: =DATEDIF(G7,TODAY(),"Y") -> 126 | I7: 646.14 | J7: tier - 3 | K7: tier - 3 | L7: R1012 | M7: =IF(L7="?","Unknown",L7) -> R1012 | W7: =DATEDIF(F7,TODAY(),"Y") -> 24 | X7: =VLOOKUP($A7,'Medical Examinations'!$A:$Z,MATCH(X$1,'Medical Examinations'!$A$1:$Z$1,0),FALSE) -> 4.29 | Y7: =DATEDIF(X7,TODAY(),"Y") -> 126 | Z7: =VLOOKUP($A7,'Medical Examinations'!$A:$Z,2,FALSE) -> 22.24
A8: Id2329 | B8: 1993 | C8: Jun | D8: =IF(C8="?","Sep",C8) -> Jun | E8: 1 | F8: =TEXT(DATE(B8,MONTH(DATEVALUE(D8&" 1")),E8),"dd-mmm-yyyy") -> 01-Jun-1993 | G8: 0 | H8: =DATEDIF(G8,TODAY(),"Y") -> 126 | I8: 650 | J8: tier - 3 | K8: tier - 3 | L8: R1013 | M8: =IF(L8="?","Unknown",L8) -> R1013 | W8: =DATEDIF(F8,TODAY(),"Y") -> 33 | X8: =VLOOKUP($A8,'Medical Examinations'!$A:$Z,MATCH(X$1,'Medical Examinations'!$A$1:$Z$1,0),FALSE) -> 5.22 | Y8: =DATEDIF(X8,TODAY(),"Y") -> 126 | Z8: =VLOOKUP($A8,'Medical Examinations'!$A:$Z,2,FALSE) -> 17.07
A9: Id2328 | B9: 1995 | C9: Jul | D9: =IF(C9="?","Sep",C9) -> Jul | E9: 4 | F9: =TEXT(DATE(B9,MONTH(DATEVALUE(D9&" 1")),E9),"dd-mmm-yyyy") -> 04-Jul-1995 | G9: 0 | H9: =DATEDIF(G9,TODAY(),"Y") -> 126 | I9: 650 | J9: tier - 3 | K9: tier - 3 | L9: R1013 | M9: =IF(L9="?","Unknown",L9) -> R1013 | W9: =DATEDIF(F9,TODAY(),"Y") -> 31 | X9: =VLOOKUP($A9,'Medical Examinations'!$A:$Z,MATCH(X$1,'Medical Examinations'!$A$1:$Z$1,0),FALSE) -> 5.26 | Y9: =DATEDIF(X9,TODAY(),"Y") -> 126 | Z9: =VLOOKUP($A9,'Medical Examinations'!$A:$Z,2,FALSE) -> 17.82
A10: Id2327 | B10: 2002 | C10: Nov | D10: =IF(C10="?","Sep",C10) -> Nov | E10: 29 | F10: =TEXT(DATE(B10,MONTH(DATEVALUE(D10&" 1")),E10),"dd-mmm-yyyy") -> 29-Nov-2002 | G10: 0 | H10: =DATEDIF(G10,TODAY(),"Y") -> 126 | I10: 668 | J10: tier - 3 | K10: tier - 2 | L10: R1012 | M10: =IF(L10="?","Unknown",L10) -> R1012 | W10: =DATEDIF(F10,TODAY(),"Y") -> 23 | X10: =VLOOKUP($A10,'Medical Examinations'!$A:$Z,MATCH(X$1,'Medical Examinations'!$A$1:$Z$1,0),FALSE) -> 10.67 | Y10: =DATEDIF(X10,TODAY(),"Y") -> 126 | Z10: =VLOOKUP($A10,'Medical Examinations'!$A:$Z,2,FALSE) -> 21.77
A11: Id2326 | B11: 1997 | C11: Nov | D11: =IF(C11="?","Sep",C11) -> Nov | E11: 9 | F11: =TEXT(DATE(B11,MONTH(DATEVALUE(D11&" 1")),E11),"dd-mmm-yyyy") -> 09-Nov-1997 | G11: 0 | H11: =DATEDIF(G11,TODAY(),"Y") -> 126 | I11: 670 | J11: tier - 3 | K11: tier - 3 | L11: R1013 | M11: =IF(L11="?","Unknown",L11) -> R1013 | W11: =DATEDIF(F11,TODAY(),"Y") -> 28 | X11: =VLOOKUP($A11,'Medical Examinations'!$A:$Z,MATCH(X$1,'Medical Examinations'!$A$1:$Z$1,0),FALSE) -> 5.6 | Y11: =DATEDIF(X11,TODAY(),"Y") -> 126 | Z11: =VLOOKUP($A11,'Medical Examinations'!$A:$Z,2,FALSE) -> 20.1
A12: Id2325 | B12: 2001 | C12: Sep | D12: =IF(C12="?","Sep",C12) -> Sep | E12: 12 | F12: =TEXT(DATE(B12,MONTH(DATEVALUE(D12&" 1")),E12),"dd-mmm-yyyy") -> 12-Sep-2001 | G12: 0 | H12: =DATEDIF(G12,TODAY(),"Y") -> 126 | I12: 687.54 | J12: tier - 3 | K12: tier - 2 | L12: R1013 | M12: =IF(L12="?","Unknown",L12) -> R1013 | W12: =DATEDIF(F12,TODAY(),"Y") -> 25 | X12: =VLOOKUP($A12,'Medical Examinations'!$A:$Z,MATCH(X$1,'Medical Examinations'!$A$1:$Z$1,0),FALSE) -> 4.54 | Y12: =DATEDIF(X12,TODAY(),"Y") -> 126 | Z12: =VLOOKUP($A12,'Medical Examinations'!$A:$Z,2,FALSE) -> 24.76
A13: Id2324 | B13: 1999 | C13: Dec | D13: =IF(C13="?","Sep",C13) -> Dec | E13: 26 | F13: =TEXT(DATE(B13,MONTH(DATEVALUE(D13&" 1")),E13),"dd-mmm-yyyy") -> 26-Dec-1999 | G13: 0 | H13: =DATEDIF(G13,TODAY(),"Y") -> 126 | I13: 700 | J13: tier - 3 | K13: tier - 3 | L13: R1013 | M13: =IF(L13="?","Unknown",L13) -> R1013 | W13: =DATEDIF(F13,TODAY(),"Y") -> 26 | X13: =VLOOKUP($A13,'Medical Examinations'!$A:$Z,MATCH(X$1,'Medical Examinations'!$A$1:$Z$1,0),FALSE) -> 5.04 | Y13: =DATEDIF(X13,TODAY(),"Y") -> 126 | Z13: =VLOOKUP($A13,'Medical Examinations'!$A:$Z,2,FALSE) -> 22.24
A14: Id2323 | B14: 1999 | C14: Dec | D14: =IF(C14="?","Sep",C14) -> Dec | E14: 14 | F14: =TEXT(DATE(B14,MONTH(DATEVALUE(D14&" 1")),E14),"dd-mmm-yyyy") -> 14-Dec-1999 | G14: 0 | H14: =DATEDIF(G14,TODAY(),"Y") -> 126 | I14: 722.99 | J14: tier - 3 | K14: tier - 1 | L14: R1013 | M14: =IF(L14="?","Unknown",L14) -> R1013 | W14: =DATEDIF(F14,TODAY(),"Y") -> 26 | X14: =VLOOKUP($A14,'Medical Examinations'!$A:$Z,MATCH(X$1,'Medical Examinations'!$A$1:$Z$1,0),FALSE) -> 5.94 | Y14: =DATEDIF(X14,TODAY(),"Y") -> 126 | Z14: =VLOOKUP($A14,'Medical Examinations'!$A:$Z,2,FALSE) -> 23.35
... A525: Id1814 | B525: 2003 | C525: Jun | D525: =IF(C525="?","Sep",C525) -> Jun | E525: 22 | F525: =TEXT(DATE(B525,MONTH(DATEVALUE(D525&" 1")),E525),"dd-mmm-yyyy") -> 22-Jun-2003 | G525: 0 | H525: =DATEDIF(G525,TODAY(),"Y") -> 126 | I525: 4687.8 | J525: tier - 2 | K525: tier - 3 | L525: R1011 | M525: =IF(L525="?","Unknown",L525) -> R1011 | W525: =DATEDIF(F525,TODAY(),"Y") -> 23 | X525: =VLOOKUP($A525,'Medical Examinations'!$A:$Z,MATCH(X$1,'Medical Examinations'!$A$1:$Z$1,0),FALSE) -> 6.08 | Y525: =DATEDIF(X525,TODAY(),"Y") -> 126 | Z525: =VLOOKUP($A525,'Medical Examinations'!$A:$Z,2,FALSE) -> 28.6
A526: Id1813 | B526: 1977 | C526: Dec | D526: =IF(C526="?","Sep",C526) -> Dec | E526: 4 | F526: =TEXT(DATE(B526,MONTH(DATEVALUE(D526&" 1")),E526),"dd-mmm-yyyy") -> 04-Dec-1977 | G526: 0 | H526: =DATEDIF(G526,TODAY(),"Y") -> 126 | I526: 4699.47 | J526: tier - 2 | K526: tier - 3 | L526: R1013 | W526: =DATEDIF(F526,TODAY(),"Y") -> 48 | X526: =VLOOKUP($A526,'Medical Examinations'!$A:$Z,MATCH(X$1,'Medical Examinations'!$A$1:$Z$1,0),FALSE) -> 5.77 | Y526: =DATEDIF(X526,TODAY(),"Y") -> 126 | Z526: =VLOOKUP($A526,'Medical Examinations'!$A:$Z,2,FALSE) -> 15.61
A527: Id1812 | B527: 1981 | C527: Aug | D527: =IF(C527="?","Sep",C527) -> Aug | E527: 12 | F527: =TEXT(DATE(B527,MONTH(DATEVALUE(D527&" 1")),E527),"dd-mmm-yyyy") -> 12-Aug-1981 | G527: 0 | H527: =DATEDIF(G527,TODAY(),"Y") -> 126 | I527: 4712.12 | J527: tier - 2 | K527: tier - 3 | L527: R1011 | W527: =DATEDIF(F527,TODAY(),"Y") -> 45 | X527: =VLOOKUP($A527,'Medical Examinations'!$A:$Z,MATCH(X$1,'Medical Examinations'!$A$1:$Z$1,0),FALSE) -> 6.6 | Y527: =DATEDIF(X527,TODAY(),"Y") -> 126 | Z527: =VLOOKUP($A527,'Medical Examinations'!$A:$Z,2,FALSE) -> 19.47
A528: Id1811 | B528: 1992 | C528: Oct | D528: =IF(C528="?","Sep",C528) -> Oct | E528: 9 | F528: =TEXT(DATE(B528,MONTH(DATEVALUE(D528&" 1")),E528),"dd-mmm-yyyy") -> 09-Oct-1992 | G528: 0 | H528: =DATEDIF(G528,TODAY(),"Y") -> 126 | I528: 4718.2 | J528: tier - 2 | K528: tier - 3 | L528: R1024 | W528: =DATEDIF(F528,TODAY(),"Y") -> 34 | X528: =VLOOKUP($A528,'Medical Examinations'!$A:$Z,MATCH(X$1,'Medical Examinations'!$A$1:$Z$1,0),FALSE) -> 5.37 | Y528: =DATEDIF(X528,TODAY(),"Y") -> 126 | Z528: =VLOOKUP($A528,'Medical Examinations'!$A:$Z,2,FALSE) -> 21.945
A529: Id1810 | B529: 1992 | C529: Sep | D529: =IF(C529="?","Sep",C529) -> Sep | E529: 28 | F529: =TEXT(DATE(B529,MONTH(DATEVALUE(D529&" 1")),E529),"dd-mmm-yyyy") -> 28-Sep-1992 | G529: 0 | H529: =DATEDIF(G529,TODAY(),"Y") -> 126 | I529: 4719.52 | J529: tier - 2 | K529: tier - 2 | L529: R1024 | W529: =DATEDIF(F529,TODAY(),"Y") -> 34 | X529: =VLOOKUP($A529,'Medical Examinations'!$A:$Z,MATCH(X$1,'Medical Examinations'!$A$1:$Z$1,0),FALSE) -> 5.24 | Y529: =DATEDIF(X529,TODAY(),"Y") -> 126 | Z529: =VLOOKUP($A529,'Medical Examinations'!$A:$Z,2,FALSE) -> 22.895
A530: Id1809 | B530: 1994 | C530: Aug | D530: =IF(C530="?","Sep",C530) -> Aug | E530: 12 | F530: =TEXT(DATE(B530,MONTH(DATEVALUE(D530&" 1")),E530),"dd-mmm-yyyy") -> 12-Aug-1994 | G530: 0 | H530: =DATEDIF(G530,TODAY(),"Y") -> 126 | I530: 4719.74 | J530: tier - 2 | K530: tier - 1 | L530: R1012 | W530: =DATEDIF(F530,TODAY(),"Y") -> 32 | X530: =VLOOKUP($A530,'Medical Examinations'!$A:$Z,MATCH(X$1,'Medical Examinations'!$A$1:$Z$1,0),FALSE) -> 4.36 | Y530: =DATEDIF(X530,TODAY(),"Y") -> 126 | Z530: =VLOOKUP($A530,'Medical Examinations'!$A:$Z,2,FALSE) -> 23.845
A531: Id1808 | B531: 1980 | C531: Jul | D531: =IF(C531="?","Sep",C531) -> Jul | E531: 2 | F531: =TEXT(DATE(B531,MONTH(DATEVALUE(D531&" 1")),E531),"dd-mmm-yyyy") -> 02-Jul-1980 | G531: 0 | H531: =DATEDIF(G531,TODAY(),"Y") -> 126 | I531: 4728.71 | J531: tier - 2 | K531: tier - 3 | L531: R1012 | W531: =DATEDIF(F531,TODAY(),"Y") -> 46 | X531: =VLOOKUP($A531,'Medical Examinations'!$A:$Z,MATCH(X$1,'Medical Examinations'!$A$1:$Z$1,0),FALSE) -> 6.07 | Y531: =DATEDIF(X531,TODAY(),"Y") -> 126 | Z531: =VLOOKUP($A531,'Medical Examinations'!$A:$Z,2,FALSE) -> 15.57
A532: Id1807 | B532: 1986 | C532: Sep | D532: =IF(C532="?","Sep",C532) -> Sep | E532: 5 | F532: =TEXT(DATE(B532,MONTH(DATEVALUE(D532&" 1")),E532),"dd-mmm-yyyy") -> 05-Sep-1986 | G532: 0 | H532: =DATEDIF(G532,TODAY(),"Y") -> 126 | I532: 4734.64 | J532: tier - 2 | K532: tier - 1 | L532: R1013 | W532: =DATEDIF(F532,TODAY(),"Y") -> 40 | X532: =VLOOKUP($A532,'Medical Examinations'!$A:$Z,MATCH(X$1,'Medical Examinations'!$A$1:$Z$1,0),FALSE) -> 11.69 | Y532: =DATEDIF(X532,TODAY(),"Y") -> 126 | Z532: =VLOOKUP($A532,'Medical Examinations'!$A:$Z,2,FALSE) -> 20.74
A533: Id1806 | B533: 1991 | C533: Oct | D533: =IF(C533="?","Sep",C533) -> Oct | E533: 12 | F533: =TEXT(DATE(B533,MONTH(DATEVALUE(D533&" 1")),E533),"dd-mmm-yyyy") -> 12-Oct-1991 | G533: 0 | H533: =DATEDIF(G533,TODAY(),"Y") -> 126 | I533: 4738.27 | J533: tier - 2 | K533: tier - 3 | L533: R1012 | W533: =DATEDIF(F533,TODAY(),"Y") -> 35 | X533: =VLOOKUP($A533,'Medical Examinations'!$A:$Z,MATCH(X$1,'Medical Examinations'!$A$1:$Z$1,0),FALSE) -> 5.44 | Y533: =DATEDIF(X533,TODAY(),"Y") -> 126 | Z533: =VLOOKUP($A533,'Medical Examinations'!$A:$Z,2,FALSE) -> 32.68
A534: Id1805 | B534: 2004 | C534: Nov | D534: =IF(C534="?","Sep",C534) -> Nov | E534: 24 | F534: =TEXT(DATE(B534,MONTH(DATEVALUE(D534&" 1")),E534),"dd-mmm-yyyy") -> 24-Nov-2004 | G534: 0 | H534: =DATEDIF(G534,TODAY(),"Y") -> 126 | I534: 4740.78 | J534: tier - 2 | K534: tier - 3 | L534: R1021 | W534: =DATEDIF(F534,TODAY(),"Y") -> 21 | X534: =VLOOKUP($A534,'Medical Examinations'!$A:$Z,MATCH(X$1,'Medical Examinations'!$A$1:$Z$1,0),FALSE) -> 5.43 | Y534: =DATEDIF(X534,TODAY(),"Y") -> 126 | Z534: =VLOOKUP($A534,'Medical Examinations'!$A:$Z,2,FALSE) -> 35.93
A535: Id1804 | B535: 1987 | C535: Jun | D535: =IF(C535="?","Sep",C535) -> Jun | E535: 5 | F535: =TEXT(DATE(B535,MONTH(DATEVALUE(D535&" 1")),E535),"dd-mmm-yyyy") -> 05-Jun-1987 | G535: 0 | H535: =DATEDIF(G535,TODAY(),"Y") -> 126 | I535: 4746.34 | J535: tier - 2 | K535: tier - 2 | L535: R1011 | W535: =DATEDIF(F535,TODAY(),"Y") -> 39 | X535: =VLOOKUP($A535,'Medical Examinations'!$A:$Z,MATCH(X$1,'Medical Examinations'!$A$1:$Z$1,0),FALSE) -> 5.08 | Y535: =DATEDIF(X535,TODAY(),"Y") -> 126 | Z535: =VLOOKUP($A535,'Medical Examinations'!$A:$Z,2,FALSE) -> 27.1
A536: Id1803 | B536: 1987 | C536: Sep | D536: =IF(C536="?","Sep",C536) -> Sep | E536: 2 | F536: =TEXT(DATE(B536,MONTH(DATEVALUE(D536&" 1")),E536),"dd-mmm-yyyy") -> 02-Sep-1987 | G536: 0 | H536: =DATEDIF(G536,TODAY(),"Y") -> 126 | I536: 4747.05 | J536: tier - 2 | K536: tier - 2 | L536: R1013 | W536: =DATEDIF(F536,TODAY(),"Y") -> 39 | X536: =VLOOKUP($A536,'Medical Examinations'!$A:$Z,MATCH(X$1,'Medical Examinations'!$A$1:$Z$1,0),FALSE) -> 4.6 | Y536: =DATEDIF(X536,TODAY(),"Y") -> 126 | Z536: =VLOOKUP($A536,'Medical Examinations'!$A:$Z,2,FALSE) -> 27.61
A537: Id1802 | B537: 1987 | C537: Nov | D537: =IF(C537="?","Sep",C537) -> Nov | E537: 22 | F537: =TEXT(DATE(B537,MONTH(DATEVALUE(D537&" 1")),E537),"dd-mmm-yyyy") -> 22-Nov-1987 | G537: 0 | H537: =DATEDIF(G537,TODAY(),"Y") -> 126 | I537: 4751.07 | J537: tier - 3 | K537: tier - 1 | L537: R1011 | W537: =DATEDIF(F537,TODAY(),"Y") -> 38 | X537: =VLOOKUP($A537,'Medical Examinations'!$A:$Z,MATCH(X$1,'Medical Examinations'!$A$1:$Z$1,0),FALSE) -> 4.81 | Y537: =DATEDIF(X537,TODAY(),"Y") -> 126 | Z537: =VLOOKUP($A537,'Medical Examinations'!$A:$Z,2,FALSE) -> 30.5
... A1050: Id1290 | B1050: 1977 | C1050: Jul | D1050: =IF(C1050="?","Sep",C1050) -> Jul | E1050: 26 | F1050: =TEXT(DATE(B1050,MONTH(DATEVALUE(D1050&" 1")),E1050),"dd-mmm-yyyy") -> 26-Jul-1977 | G1050: 0 | H1050: =DATEDIF(G1050,TODAY(),"Y") -> 126 | I1050: 8527.53 | J1050: tier - 2 | K1050: tier - 2 | L1050: R1013 | W1050: =DATEDIF(F1050,TODAY(),"Y") -> 49 | X1050: =VLOOKUP($A1050,'Medical Examinations'!$A:$Z,MATCH(X$1,'Medical Examinations'!$A$1:$Z$1,0),FALSE) -> 4.61 | Y1050: =DATEDIF(X1050,TODAY(),"Y") -> 126 | Z1050: =VLOOKUP($A1050,'Medical Examinations'!$A:$Z,2,FALSE) -> 36.3
A1051: Id1289 | B1051: ? | C1051: Jul | D1051: =IF(C1051="?","Sep",C1051) -> Jul | E1051: 24 | F1051: =TEXT(DATE(B1051,MONTH(DATEVALUE(D1051&" 1")),E1051),"dd-mmm-yyyy") -> #VALUE! | G1051: 0 | H1051: =DATEDIF(G1051,TODAY(),"Y") -> 126 | I1051: 8534.67 | J1051: tier - 2 | K1051: tier - 3 | L1051: R1024 | W1051: =DATEDIF(F1051,TODAY(),"Y") -> #VALUE! | X1051: =VLOOKUP($A1051,'Medical Examinations'!$A:$Z,MATCH(X$1,'Medical Examinations'!$A$1:$Z$1,0),FALSE) -> 11.56 | Y1051: =DATEDIF(X1051,TODAY(),"Y") -> 126 | Z1051: =VLOOKUP($A1051,'Medical Examinations'!$A:$Z,2,FALSE) -> 24.32
A1052: Id1288 | B1052: 1981 | C1052: Dec | D1052: =IF(C1052="?","Sep",C1052) -> Dec | E1052: 27 | F1052: =TEXT(DATE(B1052,MONTH(DATEVALUE(D1052&" 1")),E1052),"dd-mmm-yyyy") -> 27-Dec-1981 | G1052: 0 | H1052: =DATEDIF(G1052,TODAY(),"Y") -> 126 | I1052: 8538.29 | J1052: tier - 2 | K1052: tier - 3 | L1052: R1024 | W1052: =DATEDIF(F1052,TODAY(),"Y") -> 44 | X1052: =VLOOKUP($A1052,'Medical Examinations'!$A:$Z,MATCH(X$1,'Medical Examinations'!$A$1:$Z$1,0),FALSE) -> 8.38 | Y1052: =DATEDIF(X1052,TODAY(),"Y") -> 126 | Z1052: =VLOOKUP($A1052,'Medical Examinations'!$A:$Z,2,FALSE) -> 33.155
A1053: Id1287 | B1053: 1975 | C1053: Nov | D1053: =IF(C1053="?","Sep",C1053) -> Nov | E1053: 6 | F1053: =TEXT(DATE(B1053,MONTH(DATEVALUE(D1053&" 1")),E1053),"dd-mmm-yyyy") -> 06-Nov-1975 | G1053: 0 | H1053: =DATEDIF(G1053,TODAY(),"Y") -> 126 | I1053: 8539.67 | J1053: tier - 2 | K1053: tier - 3 | L1053: R1011 | W1053: =DATEDIF(F1053,TODAY(),"Y") -> 50 | X1053: =VLOOKUP($A1053,'Medical Examinations'!$A:$Z,MATCH(X$1,'Medical Examinations'!$A$1:$Z$1,0),FALSE) -> 7.4 | Y1053: =DATEDIF(X1053,TODAY(),"Y") -> 126 | Z1053: =VLOOKUP($A1053,'Medical Examinations'!$A:$Z,2,FALSE) -> 23.6
A1054: Id1286 | B1054: ? | C1054: Dec | D1054: =IF(C1054="?","Sep",C1054) -> Dec | E1054: 12 | F1054: =TEXT(DATE(B1054,MONTH(DATEVALUE(D1054&" 1")),E1054),"dd-mmm-yyyy") -> #VALUE! | G1054: 0 | H1054: =DATEDIF(G1054,TODAY(),"Y") -> 126 | I1054: 8547.69 | J1054: tier - 2 | K1054: tier - 1 | L1054: R1013 | W1054: =DATEDIF(F1054,TODAY(),"Y") -> #VALUE! | X1054: =VLOOKUP($A1054,'Medical Examinations'!$A:$Z,MATCH(X$1,'Medical Examinations'!$A$1:$Z$1,0),FALSE) -> 8.01 | Y1054: =DATEDIF(X1054,TODAY(),"Y") -> 126 | Z1054: =VLOOKUP($A1054,'Medical Examinations'!$A:$Z,2,FALSE) -> 29.37
A1055: Id1285 | B1055: 1975 | C1055: Aug | D1055: =IF(C1055="?","Sep",C1055) -> Aug | E1055: 6 | F1055: =TEXT(DATE(B1055,MONTH(DATEVALUE(D1055&" 1")),E1055),"dd-mmm-yyyy") -> 06-Aug-1975 | G1055: 0 | H1055: =DATEDIF(G1055,TODAY(),"Y") -> 126 | I1055: 8551.35 | J1055: tier - 2 | K1055: tier - 2 | L1055: R1011 | W1055: =DATEDIF(F1055,TODAY(),"Y") -> 51 | X1055: =VLOOKUP($A1055,'Medical Examinations'!$A:$Z,MATCH(X$1,'Medical Examinations'!$A$1:$Z$1,0),FALSE) -> 7.85 | Y1055: =DATEDIF(X1055,TODAY(),"Y") -> 126 | Z1055: =VLOOKUP($A1055,'Medical Examinations'!$A:$Z,2,FALSE) -> 32
A1056: Id1284 | B1056: 1975 | C1056: Aug | D1056: =IF(C1056="?","Sep",C1056) -> Aug | E1056: 21 | F1056: =TEXT(DATE(B1056,MONTH(DATEVALUE(D1056&" 1")),E1056),"dd-mmm-yyyy") -> 21-Aug-1975 | G1056: 0 | H1056: =DATEDIF(G1056,TODAY(),"Y") -> 126 | I1056: 8556.91 | J1056: tier - 2 | K1056: tier - 1 | L1056: R1011 | W1056: =DATEDIF(F1056,TODAY(),"Y") -> 51 | X1056: =VLOOKUP($A1056,'Medical Examinations'!$A:$Z,MATCH(X$1,'Medical Examinations'!$A$1:$Z$1,0),FALSE) -> 11.94 | Y1056: =DATEDIF(X1056,TODAY(),"Y") -> 126 | Z1056: =VLOOKUP($A1056,'Medical Examinations'!$A:$Z,2,FALSE) -> 36
A1057: Id1283 | B1057: 1988 | C1057: Sep | D1057: =IF(C1057="?","Sep",C1057) -> Sep | E1057: 21 | F1057: =TEXT(DATE(B1057,MONTH(DATEVALUE(D1057&" 1")),E1057),"dd-mmm-yyyy") -> 21-Sep-1988 | G1057: 0 | H1057: =DATEDIF(G1057,TODAY(),"Y") -> 126 | I1057: 8567.25 | J1057: tier - 2 | K1057: tier - 1 | L1057: R1012 | W1057: =DATEDIF(F1057,TODAY(),"Y") -> 38 | X1057: =VLOOKUP($A1057,'Medical Examinations'!$A:$Z,MATCH(X$1,'Medical Examinations'!$A$1:$Z$1,0),FALSE) -> 4.82 | Y1057: =DATEDIF(X1057,TODAY(),"Y") -> 126 | Z1057: =VLOOKUP($A1057,'Medical Examinations'!$A:$Z,2,FALSE) -> 31.93
A1058: Id1282 | B1058: 1975 | C1058: Sep | D1058: =IF(C1058="?","Sep",C1058) -> Sep | E1058: 26 | F1058: =TEXT(DATE(B1058,MONTH(DATEVALUE(D1058&" 1")),E1058),"dd-mmm-yyyy") -> 26-Sep-1975 | G1058: 0 | H1058: =DATEDIF(G1058,TODAY(),"Y") -> 126 | I1058: 8569.86 | J1058: tier - 2 | K1058: tier - 3 | L1058: R1013 | W1058: =DATEDIF(F1058,TODAY(),"Y") -> 51 | X1058: =VLOOKUP($A1058,'Medical Examinations'!$A:$Z,MATCH(X$1,'Medical Examinations'!$A$1:$Z$1,0),FALSE) -> 6.53 | Y1058: =DATEDIF(X1058,TODAY(),"Y") -> 126 | Z1058: =VLOOKUP($A1058,'Medical Examinations'!$A:$Z,2,FALSE) -> 45.32
A1059: Id1281 | B1059: 1982 | C1059: Dec | D1059: =IF(C1059="?","Sep",C1059) -> Dec | E1059: 6 | F1059: =TEXT(DATE(B1059,MONTH(DATEVALUE(D1059&" 1")),E1059),"dd-mmm-yyyy") -> 06-Dec-1982 | G1059: 0 | H1059: =DATEDIF(G1059,TODAY(),"Y") -> 126 | I1059: 8572.04 | J1059: tier - 2 | K1059: tier - 2 | L1059: R1021 | W1059: =DATEDIF(F1059,TODAY(),"Y") -> 43 | X1059: =VLOOKUP($A1059,'Medical Examinations'!$A:$Z,MATCH(X$1,'Medical Examinations'!$A$1:$Z$1,0),FALSE) -> 5.52 | Y1059: =DATEDIF(X1059,TODAY(),"Y") -> 126 | Z1059: =VLOOKUP($A1059,'Medical Examinations'!$A:$Z,2,FALSE) -> 26.36
A1060: Id1280 | B1060: 1987 | C1060: Nov | D1060: =IF(C1060="?","Sep",C1060) -> Nov | E1060: 11 | F1060: =TEXT(DATE(B1060,MONTH(DATEVALUE(D1060&" 1")),E1060),"dd-mmm-yyyy") -> 11-Nov-1987 | G1060: 0 | H1060: =DATEDIF(G1060,TODAY(),"Y") -> 126 | I1060: 8573.3 | J1060: tier - 2 | K1060: tier - 2 | L1060: R1021 | W1060: =DATEDIF(F1060,TODAY(),"Y") -> 38 | X1060: =VLOOKUP($A1060,'Medical Examinations'!$A:$Z,MATCH(X$1,'Medical Examinations'!$A$1:$Z$1,0),FALSE) -> 4.25 | Y1060: =DATEDIF(X1060,TODAY(),"Y") -> 126 | Z1060: =VLOOKUP($A1060,'Medical Examinations'!$A:$Z,2,FALSE) -> 30.15
A1061: Id1279 | B1061: 1983 | C1061: Dec | D1061: =IF(C1061="?","Sep",C1061) -> Dec | E1061: 30 | F1061: =TEXT(DATE(B1061,MONTH(DATEVALUE(D1061&" 1")),E1061),"dd-mmm-yyyy") -> 30-Dec-1983 | G1061: 0 | H1061: =DATEDIF(G1061,TODAY(),"Y") -> 126 | I1061: 8582.3 | J1061: tier - 2 | K1061: tier - 1 | L1061: R1013 | W1061: =DATEDIF(F1061,TODAY(),"Y") -> 42 | X1061: =VLOOKUP($A1061,'Medical Examinations'!$A:$Z,MATCH(X$1,'Medical Examinations'!$A$1:$Z$1,0),FALSE) -> 4.77 | Y1061: =DATEDIF(X1061,TODAY(),"Y") -> 126 | Z1061: =VLOOKUP($A1061,'Medical Examinations'!$A:$Z,2,FALSE) -> 23.87
A1062: Id1278 | B1062: 1983 | C1062: Jul | D1062: =IF(C1062="?","Sep",C1062) -> Jul | E1062: 25 | F1062: =TEXT(DATE(B1062,MONTH(DATEVALUE(D1062&" 1")),E1062),"dd-mmm-yyyy") -> 25-Jul-1983 | G1062: 0 | H1062: =DATEDIF(G1062,TODAY(),"Y") -> 126 | I1062: 8596.83 | J1062: tier - 2 | K1062: tier - 3 | L1062: R1013 | W1062: =DATEDIF(F1062,TODAY(),"Y") -> 43 | X1062: =VLOOKUP($A1062,'Medical Examinations'!$A:$Z,MATCH(X$1,'Medical Examinations'!$A$1:$Z$1,0),FALSE) -> 5.7 | Y1062: =DATEDIF(X1062,TODAY(),"Y") -> 126 | Z1062: =VLOOKUP($A1062,'Medical Examinations'!$A:$Z,2,FALSE) -> 34.32
...

Sheet Dashboard
A1: Healthcare Data Analysis and Insights

Sheet Cancer analysis
A3: Count of Customer ID | B3: Cancer History
A4: Smoker | B4: No | C4: Yes | D4: (blank) | E4: Grand Total
A5: ? | B5: 2 | E5: 2
A6: No | B6: 1538 | C6: 307 | E6: 1845
A7: yes | B7: 404 | C7: 84 | E7: 488
A8: (blank)
A9: Grand Total | B9: 1944 | C9: 391 | E9: 2335

Sheet Transpalnt History
A3: Any Transplants | B3: Count of Any Transplants
A4: No | B4: 2191
A5: yes | B5: 144
A6: (blank)
A7: Grand Total | B7: 2335

Sheet Cancer History
A3: Count of Customer ID | B3: Smoker
A4: Cancer History | B4: ? | C4: No | D4: yes | E4: (blank) | F4: Grand Total
A5: No | B5: 2 | C5: 1538 | D5: 404 | F5: 1944
A6: Yes | C6: 307 | D6: 84 | F6: 391
A7: (blank)
A8: Grand Total | B8: 2 | C8: 1845 | D8: 488 | F8: 2335

Sheet major surgeries and average HbA
A3: Any Transplants | B3: Average of HbA1c | C3: Sum of NumberOfMajorSurgeries
A4: No | B4: 6.6704427 | C4: 1417
A5: yes | B5: 5.1876389 | C5: 162
A6: (blank)
A7: Grand Total | B7: 6.5789979 | C7: 1579

Sheet Healthcare Charges by Weight St
A3: Sum of charges | B3: Diabetes Status
A4: Weight Status | B4: Diabetes | C4: Normal | D4: Prediabetes | E4: (blank) | F4: Grand Total
A5: Normal Weight | B5: 1595715.8 | C5: 4437473 | D5: 1520343 | F5: 7553531.8
A6: Obesity | B6: 2997979.8 | C6: 6922656.9 | D6: 2880287 | F6: 12800924
A7: Overweight | B7: 1434182.1 | C7: 3629088.6 | D7: 1781699.5 | F7: 6844970.3
A8: Underweight | B8: 1164338.6 | C8: 2202772.4 | D8: 748905.08 | F8: 4116016
A9: (blank) | E9: 453454.22 | F9: 453454.22
A10: Grand Total | B10: 7192216.3 | C10: 17191991 | D10: 6931234.6 | E10: 453454.22 | F10: 31768896

Sheet Average Healthcare Charges by H
A3: Average of charges | B3: State ID
A4: Hospital tier | B4: tier - 1 | C4: tier - 2 | D4: tier - 3 | E4: (blank) | F4: Grand Total
A5: tier - 1 | B5: 4256.81 | C5: 3805.545 | D5: 3155.2467 | E5: 31107.734 | F5: 30132.419
A6: tier - 2 | B6: 2809.1318 | C6: 2819.3633 | D6: 2874.5644 | E6: 15338.35 | F6: 11873.629
A7: tier - 3 | B7: 1940.3454 | C7: 1992.8489 | D7: 2054.7245 | E7: 11348.037 | F7: 9437.6829
A8: Grand Total | B8: 2581.7158 | C8: 2654.7525 | D8: 2634.975 | E8: 16708.682 | F8: 13559.068

Sheet Healthcare
A1: Customer ID | B1: First Name | C1: BMI | D1: HbA1c | E1: Heart Issues | F1: Any Transplants | G1: Cancer History | H1: NumberOfMajorSurgeries | I1: Smoker | J1: Weight Status | K1: Diabetes Status | L1: charges | M1: Hospital tier | N1: City tier | O1: State ID
A2: Id1 | B2: =VLOOKUP($A2,'Customer Names'!$A:$C,3,FALSE) -> Hawks, | C2: =VLOOKUP($A2,'Medical Examinations'!$A:$Z,2,FALSE) -> 47.41 | D2: =VLOOKUP($A2,'Medical Examinations'!$A:$Z,MATCH(D$1,'Medical Examinations'!$A$1:$Z$1,0),FALSE) -> 7.47 | E2: =VLOOKUP($A2,'Medical Examinations'!$A:$Z,MATCH(E$1,'Medical Examinations'!$A$1:$Z$1,0),FALSE) -> No | F2: =VLOOKUP($A2,'Medical Examinations'!$A:$Z,MATCH(F$1,'Medical Examinations'!$A$1:$Z$1,0),FALSE) -> No | G2: =VLOOKUP($A2,'Medical Examinations'!$A:$Z,MATCH(G$1,'Medical Examinations'!$A$1:$Z$1,0),FALSE) -> No | H2: =VLOOKUP($A2,'Medical Examinations'!$A:$Z,MATCH(H$1,'Medical Examinations'!$A$1:$Z$1,0),FALSE) -> 0 | I2: =VLOOKUP($A2,'Medical Examinations'!$A:$Z,MATCH(I$1,'Medical Examinations'!$A$1:$Z$1,0),FALSE) -> yes | J2: =VLOOKUP($A2,'Medical Examinations'!$A:$Z,MATCH(J$1,'Medical Examinations'!$A$1:$Z$1,0),FALSE) -> Obesity | K2: =VLOOKUP($A2,'Medical Examinations'!$A:$Z,MATCH(K$1,'Medical Examinations'!$A$1:$Z$1,0),FALSE) -> Diabetes | L2: 563.84 | M2: tier - 2 | N2: tier - 3 | O2: =IF(N2="?","Unknown",N2) -> tier - 3
A3: Id2 | B3: =VLOOKUP($A3,'Customer Names'!$A:$C,3,FALSE) -> Lehner, | C3: =VLOOKUP($A3,'Medical Examinations'!$A:$Z,2,FALSE) -> 30.36 | D3: =VLOOKUP($A3,'Medical Examinations'!$A:$Z,MATCH(D$1,'Medical Examinations'!$A$1:$Z$1,0),FALSE) -> 5.77 | E3: =VLOOKUP($A3,'Medical Examinations'!$A:$Z,MATCH(E$1,'Medical Examinations'!$A$1:$Z$1,0),FALSE) -> No | F3: =VLOOKUP($A3,'Medical Examinations'!$A:$Z,MATCH(F$1,'Medical Examinations'!$A$1:$Z$1,0),FALSE) -> No | G3: =VLOOKUP($A3,'Medical Examinations'!$A:$Z,MATCH(G$1,'Medical Examinations'!$A$1:$Z$1,0),FALSE) -> No | H3: =VLOOKUP($A3,'Medical Examinations'!$A:$Z,MATCH(H$1,'Medical Examinations'!$A$1:$Z$1,0),FALSE) -> 0 | I3: =VLOOKUP($A3,'Medical Examinations'!$A:$Z,MATCH(I$1,'Medical Examinations'!$A$1:$Z$1,0),FALSE) -> yes | J3: =VLOOKUP($A3,'Medical Examinations'!$A:$Z,MATCH(J$1,'Medical Examinations'!$A$1:$Z$1,0),FALSE) -> Obesity | K3: =VLOOKUP($A3,'Medical Examinations'!$A:$Z,MATCH(K$1,'Medical Examinations'!$A$1:$Z$1,0),FALSE) -> Prediabetes | L3: 570.62 | M3: tier - 2 | N3: tier - 1 | O3: =IF(N3="?","Unknown",N3) -> tier - 1
A4: Id3 | B4: =VLOOKUP($A4,'Customer Names'!$A:$C,3,FALSE) -> Lu, | C4: =VLOOKUP($A4,'Medical Examinations'!$A:$Z,2,FALSE) -> 34.485 | D4: =VLOOKUP($A4,'Medical Examinations'!$A:$Z,MATCH(D$1,'Medical Examinations'!$A$1:$Z$1,0),FALSE) -> 11.87 | E4: =VLOOKUP($A4,'Medical Examinations'!$A:$Z,MATCH(E$1,'Medical Examinations'!$A$1:$Z$1,0),FALSE) -> yes | F4: =VLOOKUP($A4,'Medical Examinations'!$A:$Z,MATCH(F$1,'Medical Examinations'!$A$1:$Z$1,0),FALSE) -> No | G4: =VLOOKUP($A4,'Medical Examinations'!$A:$Z,MATCH(G$1,'Medical Examinations'!$A$1:$Z$1,0),FALSE) -> No | H4: =VLOOKUP($A4,'Medical Examinations'!$A:$Z,MATCH(H$1,'Medical Examinations'!$A$1:$Z$1,0),FALSE) -> 2 | I4: =VLOOKUP($A4,'Medical Examinations'!$A:$Z,MATCH(I$1,'Medical Examinations'!$A$1:$Z$1,0),FALSE) -> yes | J4: =VLOOKUP($A4,'Medical Examinations'!$A:$Z,MATCH(J$1,'Medical Examinations'!$A$1:$Z$1,0),FALSE) -> Obesity | K4: =VLOOKUP($A4,'Medical Examinations'!$A:$Z,MATCH(K$1,'Medical Examinations'!$A$1:$Z$1,0),FALSE) -> Diabetes | L4: 600 | M4: tier - 2 | N4: tier - 1 | O4: =IF(N4="?","Unknown",N4) -> tier - 1
A5: Id4 | B5: =VLOOKUP($A5,'Customer Names'!$A:$C,3,FALSE) -> Osborne, | C5: =VLOOKUP($A5,'Medical Examinations'!$A:$Z,2,FALSE) -> 38.095 | D5: =VLOOKUP($A5,'Medical Examinations'!$A:$Z,MATCH(D$1,'Medical Examinations'!$A$1:$Z$1,0),FALSE) -> 6.05 | E5: =VLOOKUP($A5,'Medical Examinations'!$A:$Z,MATCH(E$1,'Medical Examinations'!$A$1:$Z$1,0),FALSE) -> No | F5: =VLOOKUP($A5,'Medical Examinations'!$A:$Z,MATCH(F$1,'Medical Examinations'!$A$1:$Z$1,0),FALSE) -> No | G5: =VLOOKUP($A5,'Medical Examinations'!$A:$Z,MATCH(G$1,'Medical Examinations'!$A$1:$Z$1,0),FALSE) -> No | H5: =VLOOKUP($A5,'Medical Examinations'!$A:$Z,MATCH(H$1,'Medical Examinations'!$A$1:$Z$1,0),FALSE) -> 0 | I5: =VLOOKUP($A5,'Medical Examinations'!$A:$Z,MATCH(I$1,'Medical Examinations'!$A$1:$Z$1,0),FALSE) -> yes | J5: =VLOOKUP($A5,'Medical Examinations'!$A:$Z,MATCH(J$1,'Medical Examinations'!$A$1:$Z$1,0),FALSE) -> Obesity | K5: =VLOOKUP($A5,'Medical Examinations'!$A:$Z,MATCH(K$1,'Medical Examinations'!$A$1:$Z$1,0),FALSE) -> Prediabetes | L5: 604.54 | M5: tier - 3 | N5: tier - 3 | O5: =IF(N5="?","Unknown",N5) -> tier - 3
A6: Id5 | B6: =VLOOKUP($A6,'Customer Names'!$A:$C,3,FALSE) -> Kadala, | C6: =VLOOKUP($A6,'Medical Examinations'!$A:$Z,2,FALSE) -> 35.53 | D6: =VLOOKUP($A6,'Medical Examinations'!$A:$Z,MATCH(D$1,'Medical Examinations'!$A$1:$Z$1,0),FALSE) -> 5.45 | E6: =VLOOKUP($A6,'Medical Examinations'!$A:$Z,MATCH(E$1,'Medical Examinations'!$A$1:$Z$1,0),FALSE) -> No | F6: =VLOOKUP($A6,'Medical Examinations'!$A:$Z,MATCH(F$1,'Medical Examinations'!$A$1:$Z$1,0),FALSE) -> No | G6: =VLOOKUP($A6,'Medical Examinations'!$A:$Z,MATCH(G$1,'Medical Examinations'!$A$1:$Z$1,0),FALSE) -> No | H6: =VLOOKUP($A6,'Medical Examinations'!$A:$Z,MATCH(H$1,'Medical Examinations'!$A$1:$Z$1,0),FALSE) -> 0 | I6: =VLOOKUP($A6,'Medical Examinations'!$A:$Z,MATCH(I$1,'Medical Examinations'!$A$1:$Z$1,0),FALSE) -> yes | J6: =VLOOKUP($A6,'Medical Examinations'!$A:$Z,MATCH(J$1,'Medical Examinations'!$A$1:$Z$1,0),FALSE) -> Obesity | K6: =VLOOKUP($A6,'Medical Examinations'!$A:$Z,MATCH(K$1,'Medical Examinations'!$A$1:$Z$1,0),FALSE) -> Normal | L6: 637.26 | M6: tier - 3 | N6: tier - 3 | O6: =IF(N6="?","Unknown",N6) -> tier - 3
A7: Id6 | B7: =VLOOKUP($A7,'Customer Names'!$A:$C,3,FALSE) -> Baker, | C7: =VLOOKUP($A7,'Medical Examinations'!$A:$Z,2,FALSE) -> 32.8 | D7: =VLOOKUP($A7,'Medical Examinations'!$A:$Z,MATCH(D$1,'Medical Examinations'!$A$1:$Z$1,0),FALSE) -> 6.59 | E7: =VLOOKUP($A7,'Medical Examinations'!$A:$Z,MATCH(E$1,'Medical Examinations'!$A$1:$Z$1,0),FALSE) -> No | F7: =VLOOKUP($A7,'Medical Examinations'!$A:$Z,MATCH(F$1,'Medical Examinations'!$A$1:$Z$1,0),FALSE) -> No | G7: =VLOOKUP($A7,'Medical Examinations'!$A:$Z,MATCH(G$1,'Medical Examinations'!$A$1:$Z$1,0),FALSE) -> No | H7: =VLOOKUP($A7,'Medical Examinations'!$A:$Z,MATCH(H$1,'Medical Examinations'!$A$1:$Z$1,0),FALSE) -> 0 | I7: =VLOOKUP($A7,'Medical Examinations'!$A:$Z,MATCH(I$1,'Medical Examinations'!$A$1:$Z$1,0),FALSE) -> yes | J7: =VLOOKUP($A7,'Medical Examinations'!$A:$Z,MATCH(J$1,'Medical Examinations'!$A$1:$Z$1,0),FALSE) -> Obesity | K7: =VLOOKUP($A7,'Medical Examinations'!$A:$Z,MATCH(K$1,'Medical Examinations'!$A$1:$Z$1,0),FALSE) -> Diabetes | L7: 646.14 | M7: tier - 3 | N7: tier - 3 | O7: =IF(N7="?","Unknown",N7) -> tier - 3
A8: Id7 | B8: =VLOOKUP($A8,'Customer Names'!$A:$C,3,FALSE) -> Macpherson, | C8: =VLOOKUP($A8,'Medical Examinations'!$A:$Z,2,FALSE) -> 36.4 | D8: =VLOOKUP($A8,'Medical Examinations'!$A:$Z,MATCH(D$1,'Medical Examinations'!$A$1:$Z$1,0),FALSE) -> 6.07 | E8: =VLOOKUP($A8,'Medical Examinations'!$A:$Z,MATCH(E$1,'Medical Examinations'!$A$1:$Z$1,0),FALSE) -> No | F8: =VLOOKUP($A8,'Medical Examinations'!$A:$Z,MATCH(F$1,'Medical Examinations'!$A$1:$Z$1,0),FALSE) -> No | G8: =VLOOKUP($A8,'Medical Examinations'!$A:$Z,MATCH(G$1,'Medical Examinations'!$A$1:$Z$1,0),FALSE) -> No | H8: =VLOOKUP($A8,'Medical Examinations'!$A:$Z,MATCH(H$1,'Medical Examinations'!$A$1:$Z$1,0),FALSE) -> 0 | I8: =VLOOKUP($A8,'Medical Examinations'!$A:$Z,MATCH(I$1,'Medical Examinations'!$A$1:$Z$1,0),FALSE) -> yes | J8: =VLOOKUP($A8,'Medical Examinations'!$A:$Z,MATCH(J$1,'Medical Examinations'!$A$1:$Z$1,0),FALSE) -> Obesity | K8: =VLOOKUP($A8,'Medical Examinations'!$A:$Z,MATCH(K$1,'Medical Examinations'!$A$1:$Z$1,0),FALSE) -> Prediabetes | L8: 650 | M8: tier - 3 | N8: tier - 3 | O8: =IF(N8="?","Unknown",N8) -> tier - 3
A9: Id8 | B9: =VLOOKUP($A9,'Customer Names'!$A:$C,3,FALSE) -> Hallman, | C9: =VLOOKUP($A9,'Medical Examinations'!$A:$Z,2,FALSE) -> 36.96 | D9: =VLOOKUP($A9,'Medical Examinations'!$A:$Z,MATCH(D$1,'Medical Examinations'!$A$1:$Z$1,0),FALSE) -> 7.93 | E9: =VLOOKUP($A9,'Medical Examinations'!$A:$Z,MATCH(E$1,'Medical Examinations'!$A$1:$Z$1,0),FALSE) -> No | F9: =VLOOKUP($A9,'Medical Examinations'!$A:$Z,MATCH(F$1,'Medical Examinations'!$A$1:$Z$1,0),FALSE) -> No | G9: =VLOOKUP($A9,'Medical Examinations'!$A:$Z,MATCH(G$1,'Medical Examinations'!$A$1:$Z$1,0),FALSE) -> No | H9: =VLOOKUP($A9,'Medical Examinations'!$A:$Z,MATCH(H$1,'Medical Examinations'!$A$1:$Z$1,0),FALSE) -> 3 | I9: =VLOOKUP($A9,'Medical Examinations'!$A:$Z,MATCH(I$1,'Medical Examinations'!$A$1:$Z$1,0),FALSE) -> yes | J9: =VLOOKUP($A9,'Medical Examinations'!$A:$Z,MATCH(J$1,'Medical Examinations'!$A$1:$Z$1,0),FALSE) -> Obesity | K9: =VLOOKUP($A9,'Medical Examinations'!$A:$Z,MATCH(K$1,'Medical Examinations'!$A$1:$Z$1,0),FALSE) -> Diabetes | L9: 650 | M9: tier - 3 | N9: tier - 3 | O9: =IF(N9="?","Unknown",N9) -> tier - 3
A10: Id9 | B10: =VLOOKUP($A10,'Customer Names'!$A:$C,3,FALSE) -> Moran, | C10: =VLOOKUP($A10,'Medical Examinations'!$A:$Z,2,FALSE) -> 41.14 | D10: =VLOOKUP($A10,'Medical Examinations'!$A:$Z,MATCH(D$1,'Medical Examinations'!$A$1:$Z$1,0),FALSE) -> 9.58 | E10: =VLOOKUP($A10,'Medical Examinations'!$A:$Z,MATCH(E$1,'Medical Examinations'!$A$1:$Z$1,0),FALSE) -> yes | F10: =VLOOKUP($A10,'Medical Examinations'!$A:$Z,MATCH(F$1,'Medical Examinations'!$A$1:$Z$1,0),FALSE) -> No | G10: =VLOOKUP($A10,'Medical Examinations'!$A:$Z,MATCH(G$1,'Medical Examinations'!$A$1:$Z$1,0),FALSE) -> Yes | H10: =VLOOKUP($A10,'Medical Examinations'!$A:$Z,MATCH(H$1,'Medical Examinations'!$A$1:$Z$1,0),FALSE) -> 1 | I10: =VLOOKUP($A10,'Medical Examinations'!$A:$Z,MATCH(I$1,'Medical Examinations'!$A$1:$Z$1,0),FALSE) -> yes | J10: =VLOOKUP($A10,'Medical Examinations'!$A:$Z,MATCH(J$1,'Medical Examinations'!$A$1:$Z$1,0),FALSE) -> Obesity | K10: =VLOOKUP($A10,'Medical Examinations'!$A:$Z,MATCH(K$1,'Medical Examinations'!$A$1:$Z$1,0),FALSE) -> Diabetes | L10: 668 | M10: tier - 3 | N10: tier - 2 | O10: =IF(N10="?","Unknown",N10) -> tier - 2
A11: Id10 | B11: =VLOOKUP($A11,'Customer Names'!$A:$C,3,FALSE) -> Benner, | C11: =VLOOKUP($A11,'Medical Examinations'!$A:$Z,2,FALSE) -> 38.06 | D11: =VLOOKUP($A11,'Medical Examinations'!$A:$Z,MATCH(D$1,'Medical Examinations'!$A$1:$Z$1,0),FALSE) -> 10.79 | E11: =VLOOKUP($A11,'Medical Examinations'!$A:$Z,MATCH(E$1,'Medical Examinations'!$A$1:$Z$1,0),FALSE) -> No | F11: =VLOOKUP($A11,'Medical Examinations'!$A:$Z,MATCH(F$1,'Medical Examinations'!$A$1:$Z$1,0),FALSE) -> No | G11: =VLOOKUP($A11,'Medical Examinations'!$A:$Z,MATCH(G$1,'Medical Examinations'!$A$1:$Z$1,0),FALSE) -> No | H11: =VLOOKUP($A11,'Medical Examinations'!$A:$Z,MATCH(H$1,'Medical Examinations'!$A$1:$Z$1,0),FALSE) -> 0 | I11: =VLOOKUP($A11,'Medical Examinations'!$A:$Z,MATCH(I$1,'Medical Examinations'!$A$1:$Z$1,0),FALSE) -> yes | J11: =VLOOKUP($A11,'Medical Examinations'!$A:$Z,MATCH(J$1,'Medical Examinations'!$A$1:$Z$1,0),FALSE) -> Obesity | K11: =VLOOKUP($A11,'Medical Examinations'!$A:$Z,MATCH(K$1,'Medical Examinations'!$A$1:$Z$1,0),FALSE) -> Diabetes | L11: 670 | M11: tier - 3 | N11: tier - 3 | O11: =IF(N11="?","Unknown",N11) -> tier - 3
A12: Id11 | B12: =VLOOKUP($A12,'Customer Names'!$A:$C,3,FALSE) -> Fierro | C12: =VLOOKUP($A12,'Medical Examinations'!$A:$Z,2,FALSE) -> 37.7 | D12: =VLOOKUP($A12,'Medical Examinations'!$A:$Z,MATCH(D$1,'Medical Examinations'!$A$1:$Z$1,0),FALSE) -> 5.96 | E12: =VLOOKUP($A12,'Medical Examinations'!$A:$Z,MATCH(E$1,'Medical Examinations'!$A$1:$Z$1,0),FALSE) -> yes | F12: =VLOOKUP($A12,'Medical Examinations'!$A:$Z,MATCH(F$1,'Medical Examinations'!$A$1:$Z$1,0),FALSE) -> No | G12: =VLOOKUP($A12,'Medical Examinations'!$A:$Z,MATCH(G$1,'Medical Examinations'!$A$1:$Z$1,0),FALSE) -> No | H12: =VLOOKUP($A12,'Medical Examinations'!$A:$Z,MATCH(H$1,'Medical Examinations'!$A$1:$Z$1,0),FALSE) -> 2 | I12: =VLOOKUP($A12,'Medical Examinations'!$A:$Z,MATCH(I$1,'Medical Examinations'!$A$1:$Z$1,0),FALSE) -> yes | J12: =VLOOKUP($A12,'Medical Examinations'!$A:$Z,MATCH(J$1,'Medical Examinations'!$A$1:$Z$1,0),FALSE) -> Obesity | K12: =VLOOKUP($A12,'Medical Examinations'!$A:$Z,MATCH(K$1,'Medical Examinations'!$A$1:$Z$1,0),FALSE) -> Prediabetes | L12: 687.54 | M12: tier - 3 | N12: tier - 2 | O12: =IF(N12="?","Unknown",N12) -> tier - 2
A13: Id12 | B13: =VLOOKUP($A13,'Customer Names'!$A:$C,3,FALSE) -> Franz, | C13: =VLOOKUP($A13,'Medical Examinations'!$A:$Z,2,FALSE) -> 42.13 | D13: =VLOOKUP($A13,'Medical Examinations'!$A:$Z,MATCH(D$1,'Medical Examinations'!$A$1:$Z$1,0),FALSE) -> 11.9 | E13: =VLOOKUP($A13,'Medical Examinations'!$A:$Z,MATCH(E$1,'Medical Examinations'!$A$1:$Z$1,0),FALSE) -> No | F13: =VLOOKUP($A13,'Medical Examinations'!$A:$Z,MATCH(F$1,'Medical Examinations'!$A$1:$Z$1,0),FALSE) -> No | G13: =VLOOKUP($A13,'Medical Examinations'!$A:$Z,MATCH(G$1,'Medical Examinations'!$A$1:$Z$1,0),FALSE) -> No | H13: =VLOOKUP($A13,'Medical Examinations'!$A:$Z,MATCH(H$1,'Medical Examinations'!$A$1:$Z$1,0),FALSE) -> 0 | I13: =VLOOKUP($A13,'Medical Examinations'!$A:$Z,MATCH(I$1,'Medical Examinations'!$A$1:$Z$1,0),FALSE) -> yes | J13: =VLOOKUP($A13,'Medical Examinations'!$A:$Z,MATCH(J$1,'Medical Examinations'!$A$1:$Z$1,0),FALSE) -> Obesity | K13: =VLOOKUP($A13,'Medical Examinations'!$A:$Z,MATCH(K$1,'Medical Examinations'!$A$1:$Z$1,0),FALSE) -> Diabetes | L13: 700 | M13: tier - 3 | N13: tier - 3 | O13: =IF(N13="?","Unknown",N13) -> tier - 3
... A525: Id524 | B525: =VLOOKUP($A525,'Customer Names'!$A:$C,3,FALSE) -> Rogers, | C525: =VLOOKUP($A525,'Medical Examinations'!$A:$Z,2,FALSE) -> 46.4 | D525: =VLOOKUP($A525,'Medical Examinations'!$A:$Z,MATCH(D$1,'Medical Examinations'!$A$1:$Z$1,0),FALSE) -> 8.37 | E525: =VLOOKUP($A525,'Medical Examinations'!$A:$Z,MATCH(E$1,'Medical Examinations'!$A$1:$Z$1,0),FALSE) -> yes | F525: =VLOOKUP($A525,'Medical Examinations'!$A:$Z,MATCH(F$1,'Medical Examinations'!$A$1:$Z$1,0),FALSE) -> No | G525: =VLOOKUP($A525,'Medical Examinations'!$A:$Z,MATCH(G$1,'Medical Examinations'!$A$1:$Z$1,0),FALSE) -> Yes | H525: =VLOOKUP($A525,'Medical Examinations'!$A:$Z,MATCH(H$1,'Medical Examinations'!$A$1:$Z$1,0),FALSE) -> 1 | I525: =VLOOKUP($A525,'Medical Examinations'!$A:$Z,MATCH(I$1,'Medical Examinations'!$A$1:$Z$1,0),FALSE) -> No | J525: =VLOOKUP($A525,'Medical Examinations'!$A:$Z,MATCH(J$1,'Medical Examinations'!$A$1:$Z$1,0),FALSE) -> Obesity | K525: =VLOOKUP($A525,'Medical Examinations'!$A:$Z,MATCH(K$1,'Medical Examinations'!$A$1:$Z$1,0),FALSE) -> Diabetes | L525: 4687.8 | M525: tier - 2 | N525: tier - 3 | O525: =IF(N525="?","Unknown",N525) -> tier - 3
A526: Id525 | B526: =VLOOKUP($A526,'Customer Names'!$A:$C,3,FALSE) -> Mclaughlin, | C526: =VLOOKUP($A526,'Medical Examinations'!$A:$Z,2,FALSE) -> 51.92 | D526: =VLOOKUP($A526,'Medical Examinations'!$A:$Z,MATCH(D$1,'Medical Examinations'!$A$1:$Z$1,0),FALSE) -> 5.18 | E526: =VLOOKUP($A526,'Medical Examinations'!$A:$Z,MATCH(E$1,'Medical Examinations'!$A$1:$Z$1,0),FALSE) -> yes | F526: =VLOOKUP($A526,'Medical Examinations'!$A:$Z,MATCH(F$1,'Medical Examinations'!$A$1:$Z$1,0),FALSE) -> No | G526: =VLOOKUP($A526,'Medical Examinations'!$A:$Z,MATCH(G$1,'Medical Examinations'!$A$1:$Z$1,0),FALSE) -> Yes | H526: =VLOOKUP($A526,'Medical Examinations'!$A:$Z,MATCH(H$1,'Medical Examinations'!$A$1:$Z$1,0),FALSE) -> 1 | I526: =VLOOKUP($A526,'Medical Examinations'!$A:$Z,MATCH(I$1,'Medical Examinations'!$A$1:$Z$1,0),FALSE) -> No | J526: =VLOOKUP($A526,'Medical Examinations'!$A:$Z,MATCH(J$1,'Medical Examinations'!$A$1:$Z$1,0),FALSE) -> Obesity | K526: =VLOOKUP($A526,'Medical Examinations'!$A:$Z,MATCH(K$1,'Medical Examinations'!$A$1:$Z$1,0),FALSE) -> Normal | L526: 4699.47 | M526: tier - 2 | N526: tier - 3
A527: Id526 | B527: =VLOOKUP($A527,'Customer Names'!$A:$C,3,FALSE) -> Ziegler, | C527: =VLOOKUP($A527,'Medical Examinations'!$A:$Z,2,FALSE) -> 32.395 | D527: =VLOOKUP($A527,'Medical Examinations'!$A:$Z,MATCH(D$1,'Medical Examinations'!$A$1:$Z$1,0),FALSE) -> 5.68 | E527: =VLOOKUP($A527,'Medical Examinations'!$A:$Z,MATCH(E$1,'Medical Examinations'!$A$1:$Z$1,0),FALSE) -> yes | F527: =VLOOKUP($A527,'Medical Examinations'!$A:$Z,MATCH(F$1,'Medical Examinations'!$A$1:$Z$1,0),FALSE) -> No | G527: =VLOOKUP($A527,'Medical Examinations'!$A:$Z,MATCH(G$1,'Medical Examinations'!$A$1:$Z$1,0),FALSE) -> No | H527: =VLOOKUP($A527,'Medical Examinations'!$A:$Z,MATCH(H$1,'Medical Examinations'!$A$1:$Z$1,0),FALSE) -> 1 | I527: =VLOOKUP($A527,'Medical Examinations'!$A:$Z,MATCH(I$1,'Medical Examinations'!$A$1:$Z$1,0),FALSE) -> No | J527: =VLOOKUP($A527,'Medical Examinations'!$A:$Z,MATCH(J$1,'Medical Examinations'!$A$1:$Z$1,0),FALSE) -> Obesity | K527: =VLOOKUP($A527,'Medical Examinations'!$A:$Z,MATCH(K$1,'Medical Examinations'!$A$1:$Z$1,0),FALSE) -> Normal | L527: 4712.12 | M527: tier - 2 | N527: tier - 3
A528: Id527 | B528: =VLOOKUP($A528,'Customer Names'!$A:$C,3,FALSE) -> Hughey, | C528: =VLOOKUP($A528,'Medical Examinations'!$A:$Z,2,FALSE) -> 46.19 | D528: =VLOOKUP($A528,'Medical Examinations'!$A:$Z,MATCH(D$1,'Medical Examinations'!$A$1:$Z$1,0),FALSE) -> 7.31 | E528: =VLOOKUP($A528,'Medical Examinations'!$A:$Z,MATCH(E$1,'Medical Examinations'!$A$1:$Z$1,0),FALSE) -> yes | F528: =VLOOKUP($A528,'Medical Examinations'!$A:$Z,MATCH(F$1,'Medical Examinations'!$A$1:$Z$1,0),FALSE) -> No | G528: =VLOOKUP($A528,'Medical Examinations'!$A:$Z,MATCH(G$1,'Medical Examinations'!$A$1:$Z$1,0),FALSE) -> Yes | H528: =VLOOKUP($A528,'Medical Examinations'!$A:$Z,MATCH(H$1,'Medical Examinations'!$A$1:$Z$1,0),FALSE) -> 1 | I528: =VLOOKUP($A528,'Medical Examinations'!$A:$Z,MATCH(I$1,'Medical Examinations'!$A$1:$Z$1,0),FALSE) -> No | J528: =VLOOKUP($A528,'Medical Examinations'!$A:$Z,MATCH(J$1,'Medical Examinations'!$A$1:$Z$1,0),FALSE) -> Obesity | K528: =VLOOKUP($A528,'Medical Examinations'!$A:$Z,MATCH(K$1,'Medical Examinations'!$A$1:$Z$1,0),FALSE) -> Diabetes | L528: 4718.2 | M528: tier - 2 | N528: tier - 3
